<?xml version="1.0"?>
<robot name="catatron">
  <!-- <material name="blue">
    <color rgba="0.0 0.0 1.0 1.0"/>
  </material> -->
  
  <link name="base_link">
    <visual>
      <geometry>
        <mesh filename= "/home/ajoymathew07/Catatron/Catatron/src/catatron_description/mesh_files/body_obj.obj"/>
      </geometry>
      <!-- <material name="blue"/> -->
    </visual>
    <inertial>
      <origin xyz="-0.00048043 9.0814E-05 0.00023409" rpy="0 0 0" />
      <mass value="2.000"/>
     <inertia
        ixx="0.00058474"
        ixy="-1.0045E-06"
        ixz="1.0886E-08"
        iyy="0.00029699"
        iyz="3.2027E-08"
        izz="0.00063853" />
    </inertial>
    <collision>
      <origin xyz="0.000 0.000 0.0" rpy ="0.000 0.000 0.000"/>
      <geometry>
         <mesh filename= "/home/ajoymathew07/Catatron/Catatron/src/catatron_description/mesh_files/body_obj.obj"/>
      </geometry>
  
    </collision>
  </link>
  <link name="imu_link">
    <visual>
        <geometry>
            <box size="0.05 0.05 0.01"/> 
        </geometry>
        <!-- <material name="black"/> -->
    </visual>
    <collision>
        <geometry>
            <box size="0.05 0.05 0.01"/>
        </geometry>
    </collision>
    <inertial>
        <mass value="0.05"/> 
        <origin xyz="0 0 0" rpy="0 0 0"/>
        <inertia ixx="1e-3" ixy="0.0" ixz="0.0" iyy="1e-3" iyz="0.0" izz="1e-3"/>
    </inertial>
  </link>

  <joint name="imu_joint" type="fixed">
        <parent link="base_link"/>
        <child link="imu_link"/>
        <origin xyz="0.0 0.0 0.06" rpy="0 0 0"/>
  </joint>
  <!-- <link name="lidar_link">
    <visual>
      <geometry>
        <mesh filename= "/home/ajoymathew07/Catatron/Catatron/src/catatron_description/mesh_files/dae_files/lidar.dae"/>
      </geometry>
    </visual>
    <inertial>
      <origin xyz="0.000 0.000 0.000" rpy ="0.000 0.000 0.000"/>
      <mass value="0.050"/>
      <inertia
        ixx="0.00092" ixy="0.00000" ixz="0.00001"
        iyy="0.00094" iyz="0.00000"
        izz="0.00093"/>
    </inertial>
    <collision>
      <origin xyz="0.010 0.000 -0.015" rpy ="0.000 0.000 0.000"/>
      <geometry>
        <box size="0.080 0.060 0.050"/>
      </geometry>
  
    </collision>
  </link> -->

  <link name="hip_fl_ref">
  <visual>
    <geometry>
      <box size="0.002 0.002 0.002"/>
    </geometry>
  </visual>
  <inertial>
    <origin xyz="0.000 0.000 0.000" rpy="0.000 0.000 0.000"/>
    <mass value="0.001"/> <!-- Set to a small non-zero mass -->
    <inertia
      ixx="0.00001" ixy="0.00000" ixz="0.00000"
      iyy="0.00001" iyz="0.00000" izz="0.00001"/>
  </inertial>
  <collision>
    <origin xyz="0.000 0.000 0.000" rpy="0.000 0.000 0.000"/>
    <geometry>
      <box size="0.002 0.002 0.002"/>
    </geometry>
  </collision>
  </link>


  <link name="hip_fr_ref">
    <visual>
      <geometry>
        <box size="0.002 0.002 0.002"/>
      </geometry>
    </visual>
    <inertial>
    <origin xyz="0.000 0.000 0.000" rpy="0.000 0.000 0.000"/>
    <mass value="0.001"/> <!-- Set to a small non-zero mass -->
    <inertia
      ixx="0.00001" ixy="0.00000" ixz="0.00000"
      iyy="0.00001" iyz="0.00000" izz="0.00001"/>
  </inertial>
    <collision>
      <origin xyz="0.000 0.000 0.000" rpy ="0.000 0.000 0.000"/>
      <geometry>
        <box size="0.002 0.002 0.002"/>
      </geometry>
  
    </collision>
  </link>

  <link name="hip_bl_ref">
    <visual>
      <geometry>
        <box size="0.002 0.002 0.002"/>
      </geometry>
    </visual>
    <inertial>
    <origin xyz="0.000 0.000 0.000" rpy="0.000 0.000 0.000"/>
    <mass value="0.001"/> <!-- Set to a small non-zero mass -->
    <inertia
      ixx="0.00001" ixy="0.00000" ixz="0.00000"
      iyy="0.00001" iyz="0.00000" izz="0.00001"/>
  </inertial>
    <collision>
      <origin xyz="0.000 0.000 0.000" rpy ="0.000 0.000 0.000"/>
      <geometry>
        <box size="0.002 0.002 0.002"/>
      </geometry>
  
    </collision>
  </link>

  <link name="hip_br_ref">
    <visual>
      <geometry>
        <box size="0.002 0.002 0.002"/>
      </geometry>
    </visual>
    <inertial>
    <origin xyz="0.000 0.000 0.000" rpy="0.000 0.000 0.000"/>
    <mass value="0.001"/> <!-- Set to a small non-zero mass -->
    <inertia
      ixx="0.00001" ixy="0.00000" ixz="0.00000"
      iyy="0.00001" iyz="0.00000" izz="0.00001"/>
  </inertial>
    <collision>
      <origin xyz="0.000 0.000 0.000" rpy ="0.000 0.000 0.000"/>
      <geometry>
        <box size="0.002 0.002 0.002"/>
      </geometry>
  
    </collision>
  </link>

  <link name="hip_fl_link">
    <visual>
      <geometry>
        <mesh filename= "/home/ajoymathew07/Catatron/Catatron/src/catatron_description/mesh_files/FL1_obj.obj"/>
      </geometry>
    </visual>
    <inertial>
      <origin xyz="-0.011124 -0.0032814 0.00014476" rpy="0 0 0" />
      <mass value="0.233"/>
       <inertia
        ixx="4.4732E-05"
        ixy="1.0746E-05"
        ixz="1.7651E-07"
        iyy="4.3482E-05"
        iyz="-7.8105E-08"
        izz="6.8645E-05" />
    </inertial>
    <collision>
      <origin xyz="-0.00 -0.00 0.00" rpy ="0.000 0.000 0.000"/>
      <geometry>
        <mesh filename= "/home/ajoymathew07/Catatron/Catatron/src/catatron_description/mesh_files/FL1_obj.obj"/>
      </geometry>
  
    </collision>
  </link>

  <link name="hip_fr_link">
    <visual>
      <geometry>
        <mesh filename= "/home/ajoymathew07/Catatron/Catatron/src/catatron_description/mesh_files/FR1_obj.obj"/>
      </geometry>
    </visual>
    <inertial>
      <origin xyz="0.011092 -0.0032719 0.00019267" rpy="0 0 0" />
      <mass value="0.233"/>
      <inertia
        ixx="0.00216" ixy="0.00001" ixz="0.00001"
        iyy="0.00216" iyz="-0.00001"
        izz="0.00211"/>
    </inertial>
    <collision>
      <origin xyz="-0.00 0.00 0.00" rpy ="0.000 0.000 0.000"/>
      <geometry>
        <mesh filename= "/home/ajoymathew07/Catatron/Catatron/src/catatron_description/mesh_files/FR1_obj.obj"/>
      </geometry>
  
    </collision>
  </link>

  <link name="hip_bl_link">
    <visual>
      <geometry>
        <mesh filename= "/home/ajoymathew07/Catatron/Catatron/src/catatron_description/mesh_files/RL1_obj.obj"/>
      </geometry>
    </visual>
    <inertial>
      <origin
        xyz="-0.011092 -0.0032719 -0.00019266" rpy="0 0 0" />
      <mass value="0.233"/>
      <inertia
        ixx="0.00216" ixy="0.00001" ixz="-0.00001"
        iyy="0.00216" iyz="0.00001"
        izz="0.00211"/>
    </inertial>
    <collision>
      <origin xyz="0.00 -0.00 0.00" rpy ="0.000 0.000 0.000"/>
      <geometry>
        <mesh filename= "/home/ajoymathew07/Catatron/Catatron/src/catatron_description/mesh_files/RL1_obj.obj"/>
      </geometry>
  
    </collision>
  </link>

  <link name="hip_br_link">
    <visual>
      <geometry>
        <mesh filename= "/home/ajoymathew07/Catatron/Catatron/src/catatron_description/mesh_files/RR1_obj.obj"/>
      </geometry>
    </visual>
    <inertial>
       <origin
        xyz="0.011092 -0.0032719 -0.00019266"
        rpy="0 0 0" />
      <mass value="0.233"/>
      <inertia
        ixx="0.00216" ixy="-0.00001" ixz="-0.00001"
        iyy="0.00216" iyz="-0.00001"
        izz="0.00211"/>
    </inertial>
    <collision>
      <origin xyz="0.00 0.00 0.00" rpy ="0.000 0.000 0.000"/>
      <geometry>
        <mesh filename= "/home/ajoymathew07/Catatron/Catatron/src/catatron_description/mesh_files/RR1_obj.obj"/>
      </geometry>
  
    </collision>
  </link>

  <link name="femur_fl_link">
    <visual>
      <geometry>
        <mesh filename= "/home/ajoymathew07/Catatron/Catatron/src/catatron_description/mesh_files/L2_obj.obj"/>
      </geometry>
    </visual>
    <inertial>
      <origin
        xyz="0.038603 -0.0025578 0.0001752"
        rpy="0 0 0" />
      <mass value="0.084"/>
      <inertia
        ixx="0.00414" ixy="0.00000" ixz="0.00000"
        iyy="0.00410" iyz="0.00006"
        izz="0.00386"/>
    </inertial>
    <collision>
      <origin xyz="0.000 0.0 -0.0" rpy ="0.000 0.000 0.000"/>
      <geometry>
        <mesh filename= "/home/ajoymathew07/Catatron/Catatron/src/catatron_description/mesh_files/L2_obj.obj"/>
      </geometry>
      
    </collision>
  </link>

  <link name="femur_fr_link">
    <visual>
      <geometry>
        <mesh filename= "/home/ajoymathew07/Catatron/Catatron/src/catatron_description/mesh_files/R2_obj.obj"/>
      </geometry>
    </visual>
    <inertial>
       <origin xyz="0.038603 -0.0025578 -0.0001752" rpy="0 0 0" />
      <mass value="0.084"/>
      <inertia
        ixx="0.00414" ixy="0.00000" ixz="0.00000"
        iyy="0.00410" iyz="-0.00006"
        izz="0.00386"/>
    </inertial>
    <collision>
      <origin xyz="0.000 -0.0 -0.0" rpy ="0.000 0.000 0.000"/>
      <geometry>
        <mesh filename= "/home/ajoymathew07/Catatron/Catatron/src/catatron_description/mesh_files/R2_obj.obj"/>
      </geometry>
  
    </collision>
  </link>

  <link name="femur_bl_link">
    <visual>
      <geometry>
        <mesh filename= "/home/ajoymathew07/Catatron/Catatron/src/catatron_description/mesh_files/L2_obj.obj"/>
      </geometry>
    </visual>
    <inertial>
       <origin
        xyz="0.038603 -0.0025578 0.0001752"
        rpy="0 0 0" />
      <mass value="0.084"/>
      <inertia
        ixx="0.00414" ixy="0.00000" ixz="0.00000"
        iyy="0.00410" iyz="0.00006"
        izz="0.00386"/>
    </inertial>
    <collision>
      <origin xyz="0.000 0.0 -0.0" rpy ="0.000 0.000 0.000"/>
      <geometry>
        <mesh filename= "/home/ajoymathew07/Catatron/Catatron/src/catatron_description/mesh_files/L2_obj.obj"/>
      </geometry>
  
    </collision>
  </link>

  <link name="femur_br_link">
    <visual>
      <geometry>
        <mesh filename= "/home/ajoymathew07/Catatron/Catatron/src/catatron_description/mesh_files/R2_obj.obj"/>
      </geometry>
    </visual>
    <inertial>
       <origin
        xyz="0.038603 -0.0025578 -0.0001752"
        rpy="0 0 0" />
      <mass value="0.084"/>
      <inertia
        ixx="0.00414" ixy="0.00000" ixz="0.00000"
        iyy="0.00410" iyz="-0.00006"
        izz="0.00386"/>
    </inertial>
    <collision>
      <origin xyz="0.000 -0.0 -0.0" rpy ="0.000 0.000 0.000"/>
      <geometry>
        <mesh filename= "/home/ajoymathew07/Catatron/Catatron/src/catatron_description/mesh_files/R2_obj.obj"/>
      </geometry>
 
    </collision>
  </link>

  <link name="tibia_fl_link">
    <visual>
      <geometry>
        <mesh filename= "/home/ajoymathew07/Catatron/Catatron/src/catatron_description/mesh_files/L3_obj.obj"/>
      </geometry>
    </visual>
    <inertial>
       <origin
        xyz="0.029797 -0.0009883 9.2751E-05"
        rpy="0 0 0" />
      <mass value="0.034"/>
      <inertia
        ixx="0.00159" ixy="0.00000" ixz="-0.00001"
        iyy="0.00159" iyz="0.00000"
        izz="0.00147"/>
    </inertial>
    <collision>
      <origin xyz="0.000 -0.0 -0.0" rpy ="0.000 0.000 0.000"/>
      <geometry>
        <mesh filename= "/home/ajoymathew07/Catatron/Catatron/src/catatron_description/mesh_files/L3_obj.obj"/>
      </geometry>
  
    </collision>
  </link>

  <link name="tibia_fr_link">
    <visual>
      <geometry>
        <mesh filename= "/home/ajoymathew07/Catatron/Catatron/src/catatron_description/mesh_files/R3_obj.obj"/>
      </geometry>
    </visual>
    <inertial>
       <origin xyz="0.029797 -0.00098828 -9.2749E-05" rpy="0 0 0" />
      <mass value="0.034"/>
      <inertia
        ixx="0.00159" ixy="0.00000" ixz="-0.00001"
        iyy="0.00159" iyz="0.00000"
        izz="0.00147"/>
    </inertial>
    <collision>
      <origin xyz="0.000 -0.0 -0.0" rpy ="0.000 0.000 0.000"/>
      <geometry>
        <mesh filename= "/home/ajoymathew07/Catatron/Catatron/src/catatron_description/mesh_files/R3_obj.obj"/>
      </geometry>
  
    </collision>
  </link>

  <link name="tibia_bl_link">
    <visual>
      <geometry>
        <mesh filename= "/home/ajoymathew07/Catatron/Catatron/src/catatron_description/mesh_files/L3_obj.obj"/>
      </geometry>
    </visual>
    <inertial>
       <origin
        xyz="0.029797 -0.0009883 9.2751E-05"
        rpy="0 0 0" />
      <mass value="0.034"/>
      <inertia
        ixx="0.00159" ixy="0.00000" ixz="-0.00001"
        iyy="0.00159" iyz="0.00000"
        izz="0.00147"/>
    </inertial>
    <collision>
      <origin xyz="0.000 -0.0 -0.0" rpy ="0.000 0.000 0.000"/>
      <geometry>
        <mesh filename= "/home/ajoymathew07/Catatron/Catatron/src/catatron_description/mesh_files/L3_obj.obj"/>
      </geometry>
  
    </collision>
  </link>

  <link name="tibia_br_link">
    <visual>
      <geometry>
        <mesh filename= "/home/ajoymathew07/Catatron/Catatron/src/catatron_description/mesh_files/R3_obj.obj"/>
      </geometry>
    </visual>
    <inertial>
      <origin
        xyz="0.029797 -0.00098828 -9.2749E-05"
        rpy="0 0 0" />
      <mass value="0.034"/>
      <inertia
        ixx="0.00159" ixy="0.00000" ixz="-0.00001"
        iyy="0.00159" iyz="0.00000"
        izz="0.00147"/>
    </inertial>
    <collision>
      <origin xyz="0.000 -0.0 -0.0" rpy ="0.000 0.000 0.000"/>
      <geometry>
        <mesh filename= "/home/ajoymathew07/Catatron/Catatron/src/catatron_description/mesh_files/R3_obj.obj"/>
      </geometry>
  
    </collision>
  </link>

  <link name="feet_fl">
    <visual>
      <geometry>
        <sphere radius="0.001"/>
      </geometry>
    </visual>
    <inertial>
      <origin xyz="0.000 0.000 0.000" rpy ="0.000 0.000 0.000"/>
      <mass value="0.010"/>
      <inertia
        ixx="0.00009" ixy="0.00000" ixz="0.00000"
        iyy="0.00009" iyz="0.00000"
        izz="0.00009"/>
    </inertial>
    <collision>
      <origin xyz="0.000 0.000 0.000" rpy ="0.000 0.000 0.000"/>
      <geometry>
        <box size="0.011 0.011 0.011"/>
      </geometry>
  
    </collision>
  </link>

  <link name="feet_fr">
    <visual>
      <geometry>
        <sphere radius="0.001"/>
      </geometry>
    </visual>
    <inertial>
      <origin xyz="0.000 0.000 0.000" rpy ="0.000 0.000 0.000"/>
      <mass value="0.010"/>
      <inertia
        ixx="0.00009" ixy="0.00000" ixz="0.00000"
        iyy="0.00009" iyz="0.00000"
        izz="0.00009"/>
    </inertial>
    <collision>
      <origin xyz="0.000 0.000 0.000" rpy ="0.000 0.000 0.000"/>
      <geometry>
        <box size="0.011 0.011 0.011"/>
      </geometry>
  
    </collision>
  </link>

  <link name="feet_bl">
    <visual>
      <geometry>
        <sphere radius="0.001"/>
      </geometry>
    </visual>
    <inertial>
      <origin xyz="0.000 0.000 0.000" rpy ="0.000 0.000 0.000"/>
      <mass value="0.010"/>
      <inertia
        ixx="0.00009" ixy="0.00000" ixz="0.00000"
        iyy="0.00009" iyz="0.00000"
        izz="0.00009"/>
    </inertial>
    <collision>
      <origin xyz="0.000 0.000 0.000" rpy ="0.000 0.000 0.000"/>
      <geometry>
        <box size="0.011 0.011 0.011"/>
      </geometry>
  
    </collision>
  </link>

  <link name="feet_br">
    <visual>
      <geometry>
        <sphere radius="0.001"/>
      </geometry>
    </visual>
    <inertial>
      <origin xyz="0.000 0.000 0.000" rpy ="0.000 0.000 0.000"/>
      <mass value="0.010"/>
      <inertia
        ixx="0.00009" ixy="0.00000" ixz="0.00000"
        iyy="0.00009" iyz="0.00000"
        izz="0.00009"/>
    </inertial>
    <collision>
      <origin xyz="0.000 0.000 0.000" rpy ="0.000 0.000 0.000"/>
      <geometry>
        <box size="0.011 0.011 0.011"/>
      </geometry>
  
    </collision>
  </link>


  <!-- <joint name="lidar" type="fixed" dont_collapse="true">
    <parent link="base_link"/>
    <child  link="lidar_link"/>
    <origin xyz="0.04312 0.00000 0.08341"/>
  </joint> -->

  <joint name="fl_ref" type="fixed" dont_collapse="true">
    <parent link="base_link"/>
    <child  link="hip_fl_ref"/>
    <origin xyz="0.09170 0.05355 -0.00279"/>
  </joint>

  <joint name="fr_ref" type="fixed" dont_collapse="true">
    <parent link="base_link"/>
    <child  link="hip_fr_ref"/>
    <origin xyz="0.09170 -0.05355 -0.00279"/>
  </joint>

  <joint name="bl_ref" type="fixed" dont_collapse="true">
    <parent link="base_link"/>
    <child  link="hip_bl_ref"/>
    <origin xyz="-0.09170 0.05355 -0.00279"/>
  </joint>

  <joint name="br_ref" type="fixed" dont_collapse="true">
    <parent link="base_link"/>
    <child  link="hip_br_ref"/>
    <origin xyz="-0.09170 -0.05355 -0.00279"/>
  </joint>

  <joint name="hip1_fl" type="revolute" >
    <axis xyz="1.000 0.000 0.000"/>
    <limit effort="80.00000" lower="-3.142" upper="3.142" velocity="1.04720"/>
    <parent link="hip_fl_ref"/>
    <child  link="hip_fl_link"/>
    <origin xyz="0.00000 0.00000 0.00000"/>
  </joint>

  <joint name="hip1_fr" type="revolute" >
    <axis xyz="1.000 0.000 0.000"/>
    <limit effort="80.00000" lower="-3.142" upper="3.142" velocity="1.04720"/>
    <parent link="hip_fr_ref"/>
    <child  link="hip_fr_link"/>
    <origin xyz="0.00000 0.00000 0.00000"/>
  </joint>

  <joint name="hip1_bl" type="revolute" >
    <axis xyz="1.000 0.000 0.000"/>
    <limit effort="80.00000" lower="-3.142" upper="3.142" velocity="1.04720"/>
    <parent link="hip_bl_ref"/>
    <child  link="hip_bl_link"/>
    <origin xyz="0.00000 0.00000 0.00000"/>
  </joint>

  <joint name="hip1_br" type="revolute" >
    <axis xyz="1.000 0.000 0.000"/>
    <limit effort="80.00000" lower="-3.142" upper="3.142" velocity="1.04720"/>
    <parent link="hip_br_ref"/>
    <child  link="hip_br_link"/>
    <origin xyz="0.00000 0.00000 0.00000"/>
  </joint>

  <joint name="hip2_fl" type="revolute" >
    <axis xyz="0.000 1.000 0.000"/>
    <limit effort="80.00000" lower="-3.142" upper="3.142" velocity="1.04720"/>
    <parent link="hip_fl_link"/>
    <child  link="femur_fl_link"/>
    <origin xyz="0.00000 0.03559 0.00000"/>
  </joint>

  <joint name="hip2_fr" type="revolute" >
    <axis xyz="0.000 1.000 0.000"/>
    <limit effort="80.00000" lower="-3.142" upper="3.142" velocity="1.04720"/>
    <parent link="hip_fr_link"/>
    <child  link="femur_fr_link"/>
    <origin xyz="0.00000 -0.03559 0.00000"/>
  </joint>

  <joint name="hip2_bl" type="revolute" >
    <axis xyz="0.000 1.000 0.000"/>
    <limit effort="80.00000" lower="-3.142" upper="3.142" velocity="1.04720"/>
    <parent link="hip_bl_link"/>
    <child  link="femur_bl_link"/>
    <origin xyz="0.00000 0.03559 0.00000"/>
  </joint>

  <joint name="hip2_br" type="revolute" >
    <axis xyz="0.000 1.000 0.000"/>
    <limit effort="80.00000" lower="-3.142" upper="3.142" velocity="1.04720"/>
    <parent link="hip_br_link"/>
    <child  link="femur_br_link"/>
    <origin xyz="0.00000 -0.03559 0.00000"/>
  </joint>

  <joint name="knee_fl" type="revolute" >
    <axis xyz="0.000 1.000 0.000"/>
    <limit effort="80.00000" lower="-3.142" upper="-0.52360" velocity="1.04720"/>
    <parent link="femur_fl_link"/>
    <child  link="tibia_fl_link"/>
    <origin xyz="0.00000 0.01071 -0.09996"/>
  </joint>

  <joint name="knee_fr" type="revolute" >
    <axis xyz="0.000 1.000 0.000"/>
    <limit effort="80.00000" lower="-3.142" upper="-0.52360" velocity="1.04720"/>
    <parent link="femur_fr_link"/>
    <child  link="tibia_fr_link"/>
    <origin xyz="0.00000 -0.01071 -0.09996"/>
  </joint>

  <joint name="knee_bl" type="revolute" >
    <axis xyz="0.000 1.000 0.000"/>
    <limit effort="80.00000" lower="-3.142" upper="-0.52360" velocity="1.04720"/>
    <parent link="femur_bl_link"/>
    <child  link="tibia_bl_link"/>
    <origin xyz="0.00000 0.01071 -0.09996"/>
  </joint>

  <joint name="knee_br" type="revolute" >
    <axis xyz="0.000 1.000 0.000"/>
    <limit effort="80.00000" lower="-3.142" upper="-0.52360" velocity="1.04720"/>
    <parent link="femur_br_link"/>
    <child  link="tibia_br_link"/>
    <origin xyz="0.00000 -0.01071 -0.09996"/>
  </joint>

  <joint name="feet_fl_ref" type="fixed" dont_collapse="true">
    <parent link="tibia_fl_link"/>
    <child  link="feet_fl"/>
    <origin xyz="0.00000 -0.00834 -0.10000"/>
  </joint>

  <joint name="feet_fr_ref" type="fixed" dont_collapse="true">
    <parent link="tibia_fr_link"/>
    <child  link="feet_fr"/>
    <origin xyz="0.00000 0.00834 -0.10000"/>
  </joint>

  <joint name="feet_bl_ref" type="fixed" dont_collapse="true">
    <parent link="tibia_bl_link"/>
    <child  link="feet_bl"/>
    <origin xyz="0.00000 -0.00834 -0.10000"/>
  </joint>

  <joint name="feet_br_ref" type="fixed" dont_collapse="true">
    <parent link="tibia_br_link"/>
    <child  link="feet_br"/>
    <origin xyz="0.00000 0.00834 -0.10000"/>
  </joint>

  <gazebo reference = "tibia_fl_link">
  <mu1>68</mu1>
  <mu2>68</mu2>
  </gazebo>
  <gazebo reference = "tibia_fr_link">
  <mu1>68</mu1>
  <mu2>68</mu2>
  </gazebo>
  <gazebo reference = "tibia_bl_link">
  <mu1>68</mu1>
  <mu2>68</mu2>
  </gazebo>
  <gazebo reference = "tibia_br_link">
  <mu1>68</mu1>
  <mu2>68</mu2>
  </gazebo>
  <gazebo reference = "femur_br_link">
  <mu1>68</mu1>
  <mu2>68</mu2>
  </gazebo>
  <gazebo reference = "femur_fr_link">
  <mu1>68</mu1>
  <mu2>68</mu2>
  </gazebo>
  <gazebo reference = "femur_fl_link">
  <mu1>68</mu1>
  <mu2>68</mu2>
  </gazebo>
  <gazebo reference = "femur_bl_link">
  <mu1>68</mu1>
  <mu2>68</mu2>
  </gazebo>
  <gazebo reference="imu_link">
    <sensor name="imu_sensor" type="imu">
        <always_on>true</always_on>
        <update_rate>10</update_rate>
        <visualize>true</visualize>
        <topic>imu</topic>
        <plugin filename="libgazebo_ros_imu_sensor.so" name="imu_plugin">
            <topicName>imu</topicName>
            <bodyName>imu_link</bodyName>
            <updateRateHZ>10.0</updateRateHZ>
            <gaussianNoise>0.0</gaussianNoise>
            <xyzOffset>0 0 0</xyzOffset>
            <rpyOffset>0 0 0</rpyOffset>
            <frameName>imu_link</frameName>
            <initialOrientationAsReference>true</initialOrientationAsReference>
        </plugin>
        <pose>0 0 0 0 0 0</pose>
    </sensor>
  </gazebo>
  <ros2_control name="GazeboSystem" type="system">
  <hardware>
    <plugin>gazebo_ros2_control/GazeboSystem</plugin>
  </hardware>
  


  
  <joint name="hip1_bl">
    <command_interface name="position">
      <param name="min">-3.142</param>
      <param name="max">3.142</param>
    </command_interface>
    <state_interface name="position"/>
    <state_interface name="velocity"/>
    <state_interface name="effort"/>
  </joint>

  <joint name="hip1_fr">
    <command_interface name="position">
      <param name="min">-3.142</param>
      <param name="max">3.142</param>
    </command_interface>
    <state_interface name="position"/>
    <state_interface name="velocity"/>
    <state_interface name="effort"/>
  </joint>

  <joint name="hip1_fl">
    <command_interface name="position">
      <param name="min">-3.142</param>
      <param name="max">3.142</param>
    </command_interface>
    <state_interface name="position"/>
    <state_interface name="velocity"/>
    <state_interface name="effort"/>
  </joint>

  <joint name="hip1_br">
    <command_interface name="position">
      <param name="min">-3.142</param>
      <param name="max">3.142</param>
    </command_interface>
    <state_interface name="position"/>
    <state_interface name="velocity"/>
    <state_interface name="effort"/>
  </joint>

  
  <joint name="hip2_bl">
    <command_interface name="position">
      <param name="min">-3.142</param>
      <param name="max">3.142</param>
    </command_interface>
    <state_interface name="position"/>
    <state_interface name="velocity"/>
    <state_interface name="effort"/>
  </joint>

  <joint name="hip2_fr">
    <command_interface name="position">
      <param name="min">-3.142</param>
      <param name="max">3.142</param>
    </command_interface>
    <state_interface name="position"/>
    <state_interface name="velocity"/>
    <state_interface name="effort"/>
  </joint>

  <joint name="hip2_fl">
    <command_interface name="position">
      <param name="min">-3.142</param>
      <param name="max">3.142</param>
    </command_interface>
    <state_interface name="position"/>
    <state_interface name="velocity"/>
    <state_interface name="effort"/>
  </joint>

  <joint name="hip2_br">
    <command_interface name="position">
      <param name="min">-3.142</param>
      <param name="max">3.142</param>
    </command_interface>
    <state_interface name="position"/>
    <state_interface name="velocity"/>
    <state_interface name="effort"/>
  </joint>

  
  <joint name="knee_bl">
    <command_interface name="position">
      <param name="min">-3.142</param>
      <param name="max">3.142</param>
    </command_interface>
    <state_interface name="position"/>
    <state_interface name="velocity"/>
    <state_interface name="effort"/>
  </joint>

  <joint name="knee_fr">
    <command_interface name="position">
      <param name="min">-3.142</param>
      <param name="max">3.142</param>
    </command_interface>
    <state_interface name="position"/>
    <state_interface name="velocity"/>
    <state_interface name="effort"/>
  </joint>

  <joint name="knee_fl">
    <command_interface name="position">
      <param name="min">-3.142</param>
      <param name="max">3.142</param>
    </command_interface>
    <state_interface name="position"/>
    <state_interface name="velocity"/>
    <state_interface name="effort"/>
  </joint>

  <joint name="knee_br">
    <command_interface name="position">
      <param name="min">-3.142</param>
      <param name="max">3.142</param>
    </command_interface>
    <state_interface name="position"/>
    <state_interface name="velocity"/>
    <state_interface name="effort"/>
  </joint>
</ros2_control>

<gazebo>
  <plugin filename="libgazebo_ros2_control.so" name="gazebo_ros2_control">
    <parameters>/home/ajoymathew07/Catatron/Catatron/src/catatron_description/config/joint_controller.yaml</parameters>
  </plugin>
</gazebo> 
 <!-- Joint state publisher plugin -->
  <gazebo>
    <plugin name="joint_state_publisher" filename="libgazebo_ros_joint_state_publisher.so">
        <robotNamespace>notspot_gazebo</robotNamespace>
        <jointName>hip1_fl,hip1_fr,hip1_br,hip1_bl,
                  hip2_fl,hip2_fr,hip2_br,hip2_bl,
                  knee_fl,knee_fr,knee_br,knee_bl
        </jointName>
        <updateRate>100</updateRate>
    </plugin>
  </gazebo>

</robot>